Workbook

Sheet Test Case List
A1: TEST CASE LIST
B3: Project Name | D3: AI-Based English Grammar and Writing Improvement Tool
B4: Project Code
B5: Test Environment Setup Description | D5: 1. Google Chrome 2. Backend Flask, AI-service FastAPI 3. Groq API và Free Dictionary API
B7: No | C7: Function Name | D7: Sheet Name | E7: Description | F7: Pre-Condition
B8: 1 | C8: Nhập văn bản đầu vào | D8: =HYPERLINK("#'Text Input'!A1","Text Input") -> Text Input | E8: Nhập, dán, nhập tệp, Sample Text, Clear All và giao diện nhập liệu
B9: =B8+1 -> 2 | C9: Kiểm tra ngữ pháp | D9: =HYPERLINK("#'Grammar Check'!A1","Grammar Check") -> Grammar Check | E9: Phát hiện và sửa lỗi ngữ pháp tiếng Anh, hiển thị kết quả phân tích
B10: =B9+1 -> 3 | C10: Gợi ý viết lại bằng AI | D10: =HYPERLINK("#'AI Rewrite'!A1","AI Rewrite") -> AI Rewrite | E10: Viết lại văn bản bằng AI (Groq), hiển thị cải tiến và tóm tắt
B11: =B10+1 -> 4 | C11: Tra cứu từ vựng | D11: =HYPERLINK("#'Vocab Lookup'!A1","Vocab Lookup") -> Vocab Lookup | E11: Tra từ, cụm từ, thành ngữ qua popup và cách dùng bằng AI

Sheet Test Design
A1: Requirement Level 1 | B1: Requirement Level 2 | C1: Requirement Level 3 | D1: Test Criteria | E1: Test Type | F1: Note
A2: Text Input | B2: Kiểm tra nhập văn bản dữ liệu đầu vào | C2: Nhập văn bản | D2: Kiểm tra nhập câu tiếng Anh hợp lệ | E2: Function
D3: Kiểm tra khi để trống ô nhập | E3: Function
D4: Kiểm tra nhập văn bản có nhiều khoảng trắng giữa các từ | E4: Function
D5: Kiểm tra nhập câu tiếng Việt có dấu | E5: Function
D6: Kiểm tra nhập câu chứa ký tự đặc biệt | E6: Function
D7: Kiểm tra xuống dòng bằng phím Enter | E7: Function
D8: Kiểm tra nhập văn bản dài đúng 2000 ký tự (bằng giới hạn) | E8: Function
D9: Kiểm tra nhập văn bản dài 2001 ký tự (vượt giới hạn) | E9: Function
C10: Paste | D10: Kiểm tra dán một câu hợp lệ từ clipboard | E10: Function
D11: Kiểm tra dán văn bản gồm nhiều đoạn | E11: Function
D12: Kiểm tra dán văn bản trộn emoji và ký tự Unicode | E12: Function
D13: Kiểm tra dán khi ô nhập đã có sẵn nội dung | E13: Function
D14: Kiểm tra dán văn bản vượt quá 2000 ký tự | E14: Function
C15: Sample Text | D15: Kiểm tra nhấn Sample Text khi ô nhập đang trống | E15: Function
D16: Kiểm tra nhấn Sample Text khi ô nhập đã có chữ | E16: Function
D17: Kiểm tra nhấn Sample Text liên tục nhiều lần | E17: Function
C18: Clear All | D18: Kiểm tra nhấn Clear All khi ô nhập đang có chữ | E18: Function
D19: Kiểm tra nhấn Clear All khi ô nhập đang trống | E19: Function
D20: Kiểm tra nhấn Clear All sau khi dùng Sample Text | E20: Function
C21: Import | D21: Kiểm tra nhập tệp văn bản hợp lệ | E21: Function
D22: Kiểm tra nhập tệp có nhiều đoạn và xuống dòng | E22: Function
D23: Kiểm tra nhập tệp có chứa tiếng Việt có dấu và ký tự Unicode | E23: Function
D24: Kiểm tra nhập tệp có định dạng không được hỗ trợ | E24: Function
D25: Kiểm tra nhập tệp rỗng | E25: Function
D26: Kiểm tra nhập tệp có nội dung vượt giới hạn ký tự | E26: Function
D27: Kiểm tra nhập tệp khi ô nhập đã có sẵn nội dung | E27: Function
D28: Kiểm tra hủy thao tác chọn tệp | E28: Function
D29: Kiểm tra nhập liên tiếp hai tệp khác nhau | E29: Function
D30: Kiểm tra phân tích ngữ pháp với nội dung đã nhập từ tệp | E30: Function
D31: Kiểm tra chỉnh sửa nội dung sau khi nhập tệp | E31: Function
C32: Giao diện | D32: Kiểm tra hiển thị các thành phần Import File | E32: Function
D33: Kiểm tra giao diện Import File trên màn hình nhỏ | E33: Function
D34: Kiểm tra bố cục giao diện trên màn hình rộng 768px | E34: Function
D35: Kiểm tra giao diện trên màn hình điện thoại | E35: Function
D36: Kiểm tra hiển thị các nút chức năng và bộ đếm từ trên trang | E36: Function
D37: Kiểm tra bộ đếm từ cập nhật theo nội dung khi nhập và xóa | E37: Function
D38: Kiểm tra hiển thị văn bản dài trong ô nhập | E38: Function
A39: Grammar Check | B39: Kiểm tra ngữ pháp sửa lỗi tiếng Anh | C39: Ngữ pháp sửa lỗi tiếng Anh | D39: Kiểm tra câu đúng ngữ pháp | E39: Function
D40: Kiểm tra phát hiện lỗi chia động từ ngôi thứ ba số ít | E40: Function
...

Sheet Text Input
A2: Module Code | B2: Text Input
A3: Test Requirement | B3: Kiểm tra nhập văn bản dữ liệu đầu vào
A4: Tester | B4: Nguyễn Thanh Thủy
A5: Passed | B5: Failed | C5: Untested | D5: Blocked | E5: Skipped | F5: Number of Test cases
A6: =COUNTIF($G$10:$G$995,"Passed") -> 36 | B6: =COUNTIF($G$10:$G$995,"Failed") -> 1 | C6: =COUNTIF($G$10:$G$995,"Untested") -> 0 | D6: =COUNTIF($G$10:$G$995,"Blocked") -> 0 | E6: =COUNTIF($G$10:$G$995,"Skipped") -> 0 | F6: =COUNTA($A$10:$A$995) -> 37
A8: ID | B8: Test Case Description | C8: Test Case Procedure | D8: Test Data | E8: Expected Output | F8: Inter-test case Dependence | G8: Result | H8: Test date | I8: Priority | J8: Note
B9: Nhập văn bản
A10: TEXT_INPUT_01 | B10: Kiểm tra nhập câu tiếng Anh hợp lệ | C10: 1. Truy cập trang website 2. Nhập nội dung cần kiểm tra vào ô nhập 3. Quan sát nội dung hiển thị trong ô nhập văn bản và bộ đếm từ | D10: 2. I am learning English today. | E10: 1. Hiển thị giao diện chính của trang website. 3. Ô nhập hiển thị đúng chuỗi vừa gõ. | F10: Không | G10: Passed | H10: 46316 | I10: High
A11: TEXT_INPUT_02 | B11: Kiểm tra khi để trống ô nhập | C11: 1. Truy cập trang website 2. Để trống ô nhập 3. Quan sát nội dung hiển thị trong ô nhập văn bản và bộ đếm từ | D11: 2. Để trống | E11: 1. Hiển thị giao diện chính của trang website. 3. Hệ thống không hiển thị nội dung trong ô nhập văn bản và bộ đếm từ hiển thị bằng 0. | F11: Không | G11: Passed | H11: 46316 | I11: High
A12: TEXT_INPUT_03 | B12: Kiểm tra nhập văn bản có nhiều khoảng trắng giữa các từ | C12: 1. Truy cập trang website 2. Nhập câu có nhiều dấu cách giữa các từ vào ô nhập văn bản 3. Quan sát nội dung hiển thị và bộ đếm từ | D12: 2. I love English | E12: 1. Hiển thị giao diện chính của trang website. 3. Hệ thống giữ nguyên nội dung đã nhập và đếm chính xác 3 từ. | F12: Không | G12: Passed | H12: 46316 | I12: Medium
A13: TEXT_INPUT_04 | B13: Kiểm tra nhập câu tiếng Việt có dấu | C13: 1. Truy cập trang website 2. Nhập câu tiếng Việt có dấu 3. Quan sát nội dung hiển thị trong ô nhập văn bản và bộ đếm từ | D13: 2. Tôi đang học tiếng Anh mỗi ngày. | E13: 1. Hiển thị giao diện chính của trang website. 3. Hệ thống hiển thị đúng nội dung tiếng Việt có dấu và đếm chính xác số từ trong câu. | F13: Không | G13: Passed | H13: 46316 | I13: High
A14: TEXT_INPUT_05 | B14: Kiểm tra nhập câu chứa ký tự đặc biệt | C14: 1. Truy cập trang website 2. Nhập câu chứa ký tự đặc biệt 3. Quan sát nội dung hiển thị trong ô nhập văn bản và bộ đếm từ | D14: 2. "Hello! @AI #English 100%." | E14: 1. Hiển thị giao diện chính của trang website. 3. Hệ thống hiển thị đúng các ký tự đặc biệt hợp lệ, không phát sinh lỗi và đếm chính xác số từ trong câu. | F14: Không | G14: Passed | H14: 46316 | I14: High
A15: TEXT_INPUT_06 | B15: Kiểm tra xuống dòng bằng phím Enter | C15: 1. Truy cập trang website 2. Nhập câu thứ nhất, nhấn Enter rồi nhập câu thứ hai 3. Quan sát nội dung hiển thị trong ô nhập văn bản và bộ đếm từ | D15: 2. Câu 1: First sentence. Câu 2: Second sentence. | E15: 1. Hiển thị giao diện chính của trang website. 3. Hệ thống cho phép xuống dòng khi nhấn Enter, không tự động gửi biểu mẫu và đếm chính xác 4 từ theo quy tắc đếm hiện hành. | F15: Không | G15: Passed | H15: 46316 | I15: High
A16: TEXT_INPUT_07 | B16: Kiểm tra nhập văn bản dài đúng 2000 ký tự (bằng giới hạn) | C16: 1. Truy cập trang website 2. Nhập đoạn văn bản dài đúng 2000 ký tự 3. Quan sát nội dung hiển thị trong ô nhập văn bản và bộ đếm từ | D16: 2. Chuỗi 2000 ký tự | E16: 1. Hiển thị giao diện chính của trang website. 3. Hệ thống cho phép nhập đủ 2000 ký tự và xử lý văn bản bình thường. | F16: Không | G16: Passed | H16: 46316 | I16: High
A17: TEXT_INPUT_08 | B17: Kiểm tra nhập văn bản dài 2001 ký tự (vượt giới hạn) | C17: 1. Truy cập trang website 2. Nhập đoạn văn bản dài 2001 ký tự 3. Quan sát nội dung hiển thị trong ô nhập văn bản và bộ đếm từ | D17: 2. Chuỗi 2001 ký tự | E17: 1. Hiển thị giao diện chính của trang website. 3. Hệ thống không cho phép nhập vượt quá 2000 ký tự hoặc thông báo phù hợp khi vượt giới hạn. | F17: Không | G17: Failed | H17: 46316 | I17: High
B18: Paste
A19: TEXT_PASTE_01 | B19: Kiểm tra dán một câu hợp lệ từ clipboard | C19: 1. Truy cập trang website 2. Nhấn nút [Paste] để dán nội dung từ clipboard | D19: 2. Clipboard: "Practice makes perfect." | E19: 1. Hiển thị giao diện chính của trang website. 2. Hệ thống hiển thị nội dung được dán đầy đủ và đếm đúng số từ trong câu. | F19: Không | G19: Passed | H19: 46316 | I19: High
A20: TEXT_PASTE_02 | B20: Kiểm tra dán văn bản gồm nhiều đoạn | C20: 1. Truy cập trang website 2. Nhấn nút [Paste] để dán nội dung từ clipboard | D20: 2. Clipboard: văn bản 3 đoạn | E20: 1. Hiển thị giao diện chính của trang website. 2. Hệ thống hiển thị ba đoạn được sao chép, không mất dữ liệu và tổng số từ chính xác. | F20: Không | G20: Passed | H20: 46316 | I20: High
A21: TEXT_PASTE_03 | B21: Kiểm tra dán văn bản trộn emoji và ký tự Unicode | C21: 1. Truy cập trang website 2. Sao chép nội dung kiểm thử vào clipboard và nhấn nút [Paste] 3. Quan sát nội dung hiển thị và bộ đếm từ | D21: Clipboard: I like English 😊 café résumé | E21: 1. Hiển thị giao diện chính của trang website. 3. Hệ thống hiển thị đúng các ký tự Unicode và emoji, không lỗi font, đồng thời đếm số từ theo quy tắc hiện hành. | F21: Không | G21: Passed | H21: 46316 | I21: High
A22: TEXT_PASTE_04 | B22: Kiểm tra dán khi ô nhập đã có sẵn nội dung | C22: 1. Truy cập trang website 2. Nhấn nút [Paste] để dán nội dung từ clipboard | D22: 2. Sẵn có: "Hello"; Clipboard: " world" | E22: 1. Hiển thị giao diện chính của trang website. 2. Hệ thống hiển thị nội dung dán được nối vào vị trí con trỏ và số từ cập nhật chính xác. | F22: Không | G22: Passed | H22: 46316 | I22: High
A23: TEXT_PASTE_05 | B23: Kiểm tra dán văn bản vượt quá 2000 ký tự | C23: 1. Truy cập trang website 2. Nhấn nút [Paste] để dán nội dung từ clipboard | D23: 2. Clipboard: chuỗi 2001 ký tự | E23: 1. Hiển thị giao diện chính của trang website. 2. Hệ thống chặn hoặc cắt phần vượt giới hạn và hiển thị thông báo phù hợp. | F23: Không | G23: Passed | H23: 46316 | I23: High
B24: Sample Text
A25: TEXT_SAMPLE_01 | B25: Kiểm tra nhấn Sample Text khi ô nhập đang trống | C25: 1. Truy cập trang website 2. Nhấn nút [Sample Text] | E25: 1. Hiển thị giao diện chính của trang website. 2. Hệ thống tự động điền văn bản mẫu vào ô nhập và cập nhật bộ đếm từ tương ứng. | F25: Không | G25: Passed | H25: 46316 | I25: High
A26: TEXT_SAMPLE_02 | B26: Kiểm tra nhấn Sample Text khi ô nhập đã có chữ | C26: 1. Truy cập trang website 2. Nhấn nút [Sample Text] | E26: 1. Hiển thị giao diện chính của trang website. 2. Hệ thống thay thế nội dung hiện tại bằng văn bản mẫu và cập nhật bộ đếm từ tương ứng. | F26: Không | G26: Passed | H26: 46316 | I26: High
A27: TEXT_SAMPLE_03 | B27: Kiểm tra nhấn Sample Text liên tục nhiều lần | C27: 1. Truy cập trang website 2. Nhấn nút [Sample Text] | E27: 1. Hiển thị giao diện chính của trang website. 2. Hệ thống hiển thị văn bản mẫu mà không bị nhân đôi ngoài ý muốn, giao diện hoạt động bình thường và bộ đếm từ chính xác. | F27: Không | G27: Passed | H27: 46316 | I27: High
B28: Clear All
A29: TEXT_CLEAR_01 | B29: Kiểm tra nhấn Clear All khi ô nhập đang có chữ | C29: 1. Truy cập trang website 2. Nhập một đoạn văn bản 3. Nhấn nút [Clear All] | D29: 2. This text will be cleared. | E29: 1. Hiển thị giao diện chính của trang website. 3. Toàn bộ nội dung bị xóa, số từ về 0 và các kết quả xử lý liên quan được làm mới. | F29: Không | G29: Passed | H29: 46316 | I29: High
A30: TEXT_CLEAR_02 | B30: Kiểm tra nhấn Clear All khi ô nhập đang trống | C30: 1. Truy cập trang website 2. Giữ nguyên ô nhập ở trạng thái trống 3. Nhấn nút [Clear All] | E30: 1. Hiển thị giao diện chính của trang website. 3. Hệ thống không phát sinh lỗi, ô nhập văn bản vẫn trống và bộ đếm từ hiển thị bằng 0. | F30: Không | G30: Passed | H30: 46316 | I30: High
A31: TEXT_CLEAR_03 | B31: Kiểm tra nhấn Clear All sau khi dùng Sample Text | C31: 1. Truy cập trang website 2. Nhấn nút [Sample Text] 3. Nhấn nút [Clear All] | E31: 1. Hiển thị giao diện chính của trang website. 2. Hệ thống tự động điền văn bản mẫu vào ô nhập và cập nhật bộ đếm từ tương ứng. 3. Hệ thống xóa văn bản mẫu khỏi ô nhập và đưa bộ đếm từ về 0. | F31: Không | G31: Passed | H31: 46316 | I31: High
B32: Import
A33: TEXT_IMPORT_01 | B33: Kiểm tra nhập tệp văn bản hợp lệ | C33: 1. Truy cập trang website 2. Nhấn nút [Import File] 3. Chọn một tệp văn bản thuộc định dạng được hỗ trợ 4. Nhấn nút [OK] | D33: 3. Tệp .docx hợp lệ chứa: I am learning English today. | E33: 1. Hiển thị giao diện chính của trang website. 2. Hiển thị giao diện chọn file. 4. Hệ thống hiển thị đầy đủ nội dung từ tệp đã nhập và cập nhật bộ đếm từ chính xác. | F33: Không | G33: Passed | H33: 46316 | I33: High
A34: TEXT_IMPORT_02 | B34: Kiểm tra nhập tệp có nhiều đoạn và xuống dòng | C34: 1. Truy cập trang website 2. Chọn chức năng Import File 3. Chọn tệp văn bản có nhiều đoạn 4. Nhấn nút [OK] | D34: 3. Tệp văn bản gồm 3 đoạn, có xuống dòng giữa các đoạn. | E34: 1. Hiển thị giao diện chính của trang website. 4. Hệ thống giữ nguyên nội dung và cấu trúc xuống dòng của các đoạn, không mất dữ liệu và đếm số từ theo quy tắc hiện hành. | F34: TEXT_IMPORT_01 | G34: Passed | H34: 46316 | I34: High
A35: TEXT_IMPORT_03 | B35: Kiểm tra nhập tệp có chứa tiếng Việt có dấu và ký tự Unicode | C35: 1. Truy cập trang website 2. Nhấn nút [Import File] 3. Chọn tệp văn bản mã hóa UTF-8 chứa tiếng Việt có dấu và ký tự Unicode 4. Nhấn nút [OK] | D35: 3. Tệp chứa: Tôi đang học tiếng Anh. café résumé 😊 | E35: 1. Hiển thị giao diện chính của trang website. 4. Ký tự Unicode hiển thị đúng trong ô nhập, không lỗi font hoặc ký tự lạ. | F35: Không | G35: Passed | H35: 46316 | I35: Medium
A36: TEXT_IMPORT_04 | B36: Kiểm tra nhập tệp có định dạng không được hỗ trợ | C36: 1. Truy cập trang website 2. Chọn chức năng Import File 3. Chọn một tệp có định dạng không được hỗ trợ 4. Nhấn nút [OK] | D36: 3. Tệp có định dạng không thuộc danh sách được hỗ trợ, ví dụ .exe. | E36: 1. Hiển thị giao diện chính của trang website. 4. Hệ thống từ chối tệp không được hỗ trợ và hiển thị thông báo phù hợp; giao diện không bị treo. | F36: Không | G36: Passed | H36: 46316 | I36: High
A37: TEXT_IMPORT_05 | B37: Kiểm tra nhập tệp rỗng | C37: 1. Truy cập trang website 2. Chọn chức năng Import File 3. Chọn tệp văn bản rỗng 4. Nhấn nút [OK] | D37: 3. Tệp .txt có dung lượng 0 byte. | E37: 1. Hiển thị giao diện chính của trang website. 4. Hệ thống xử lý tệp rỗng theo quy định của ứng dụng, không phát sinh lỗi không kiểm soát và hiển thị thông báo phù hợp nếu không thể nhập. | F37: TEXT_IMPORT_01 | G37: Passed | H37: 46316 | I37: Medium
A38: TEXT_IMPORT_06 | B38: Kiểm tra nhập tệp có nội dung vượt giới hạn ký tự | C38: 1. Truy cập trang website 2. Chọn chức năng Import File 3. Chọn tệp văn bản có nội dung vượt giới hạn ký tự của ô nhập 4. Nhấn nút [OK] | D38: 3. Tệp .txt có nội dung dài 2001 ký tự (giới hạn đang ghi nhận trong bộ test). | E38: 1. Hiển thị giao diện chính của trang website. 4. Hệ thống áp dụng cùng quy tắc giới hạn ký tự như nhập trực tiếp: không nhận vượt giới hạn hoặc thông báo/cắt phần dư theo yêu cầu đã xác nhận. | F38: TEXT_INPUT_07; TEXT_INPUT_08 | G38: Passed | H38: 46316 | I38: High
A39: TEXT_IMPORT_07 | B39: Kiểm tra nhập tệp khi ô nhập đã có sẵn nội dung | C39: 1. Truy cập trang website 2. Nhập một câu vào ô nhập 3. Nhấn nút [Import File] và chọn tệp văn bản hợp lệ 4. Nhấn nút [OK] 5. Quan sát ô nhập và bộ đếm từ | D39: 2. Sẵn có: Hello 3. Tệp chứa: I am learning English today. | E39: 1. Hiển thị giao diện chính của trang website. 5. Nội dung ô nhập được cập nhật theo thiết kế (thay thế hoặc nối thêm), không phát sinh lỗi và bộ đếm từ chính xác. | F39: Không | G39: Passed | H39: 46316 | I39: Medium
A40: TEXT_IMPORT_08 | B40: Kiểm tra hủy thao tác chọn tệp | C40: 1. Truy cập trang website 2. Chọn chức năng Import File 3. Mở hộp thoại chọn tệp rồi nhấn Cancel 4. Quan sát ô nhập văn bản và bộ đếm từ | D40: Ô nhập ban đầu chứa: Existing text. | E40: 1. Hiển thị giao diện chính của trang website. 4. Hệ thống đóng hộp thoại chọn tệp, giữ nguyên nội dung hiện tại và không thay đổi bộ đếm từ. | F40: Không | G40: Passed | H40: 46316 | I40: Medium
A41: TEXT_IMPORT_09 | B41: Kiểm tra nhập liên tiếp hai tệp khác nhau | C41: 1. Truy cập trang website 2. Nhấn nút [Import File], chọn tệp thứ nhất rồi nhấn nút [OK] 3. Nhấn nút [Import File], chọn tệp thứ hai rồi nhấn nút [OK] 4. Quan sát ô nhập và bộ đếm từ | D41: 2. Tệp a: First file. 3. Tệp b: Second file. | E41: 1. Hiển thị giao diện chính của trang website. 4. Nội dung hiển thị theo thiết kế, không bị lẫn hoặc nhân đôi dữ liệu; bộ đếm từ chính xác. | F41: Không | G41: Passed | H41: 46316 | I41: Medium
A42: TEXT_IMPORT_10 | B42: Kiểm tra kiểm tra ngữ pháp với nội dung đã nhập từ tệp | C42: 1. Truy cập trang website 2. Nhấn nút [Import File], chọn tệp văn bản chứa câu sai ngữ pháp rồi nhấn nút [OK] 3. Nhấn nút [Check] 4. Quan sát phần [Analysis Result] | D42: 2. Tệp chứa: He go to work by bus every morning. | E42: 1. Hiển thị giao diện chính của trang website. 4. Hệ thống phân tích nội dung đã nhập, đánh dấu lỗi "go" và gợi ý sửa thành "goes". | F42: Không | G42: Passed | H42: 46316 | I42: High
...

Sheet Grammar Check
A2: Module Code | B2: Grammar Check
A3: Test Requirement | B3: Kiểm thử chức năng ngữ pháp sửa lỗi tiếng Anh
A4: Tester | B4: Nguyễn Thanh Thủy
A5: Passed | B5: Failed | C5: Untested | D5: Blocked | E5: Skipped | F5: Number of Test cases
A6: =COUNTIF($G$10:$G$995,"Passed") -> 23 | B6: =COUNTIF($G$10:$G$995,"Failed") -> 0 | C6: =COUNTIF($G$10:$G$995,"Untested") -> 0 | D6: =COUNTIF($G$10:$G$995,"Blocked") -> 0 | E6: =COUNTIF($G$10:$G$995,"Skipped") -> 0 | F6: =COUNTA($A$10:$A$995) -> 23
A8: ID | B8: Test Case Description | C8: Test Case Procedure | D8: Test Data | E8: Expected Output | F8: Inter-test case Dependence | G8: Result | H8: Test date | I8: Priority | J8: Note
B9: Ngữ pháp sửa lỗi tiếng Anh
A10: GRAMMAR_CHECK_01 | B10: Kiểm tra câu đúng ngữ pháp | C10: 1. Truy cập trang website 2. Nhập câu đúng ngữ pháp 3. Nhấn nút [Check] | D10: 2. My brother plays football every weekend. | E10: 1. Hiển thị giao diện chính của trang website. 3. Hệ thống không phát hiện lỗi: văn bản đã sửa giống văn bản gốc, mục Detected Errors hiển thị (0) và không có từ nào bị đánh dấu. | F10: Không | G10: Passed | H10: 46317 | I10: High
A11: GRAMMAR_CHECK_02 | B11: Kiểm tra phát hiện lỗi chia động từ ngôi thứ ba số ít | C11: 1. Truy cập trang website 2. Nhập câu sai chia động từ ngôi thứ ba số ít 3. Nhấn nút [Check] | D11: 2. He go to work by bus every morning. | E11: 1. Hiển thị giao diện chính của trang website. 3. Hệ thống phát hiện lỗi ở từ "go", đánh dấu và gợi ý sửa thành "goes". | F11: Không | G11: Passed | H11: 46317 | I11: High
A12: GRAMMAR_CHECK_03 | B12: Kiểm tra phát hiện lỗi dùng sai động từ to be | C12: 1. Truy cập trang website 2. Nhập câu dùng sai động từ to be 3. Nhấn nút [Check] | D12: 2. We is ready for the exam. | E12: 1. Hiển thị giao diện chính của trang website. 3. Hệ thống phát hiện lỗi ở từ "is", đánh dấu và gợi ý sửa thành "are". | F12: Không | G12: Passed | H12: 46317 | I12: High
A13: GRAMMAR_CHECK_04 | B13: Kiểm tra phát hiện lỗi thiếu mạo từ | C13: 1. Truy cập trang website 2. Nhập câu thiếu mạo từ 3. Nhấn nút [Check] | D13: 2. She bought umbrella yesterday. | E13: 1. Hiển thị giao diện chính của trang website. 3. Hệ thống phát hiện thiếu mạo từ và gợi ý sửa "bought umbrella" thành "bought an umbrella". | F13: Không | G13: Passed | H13: 46317 | I13: High
A14: GRAMMAR_CHECK_05 | B14: Kiểm tra phát hiện lỗi danh từ số ít/số nhiều | C14: 1. Truy cập trang website 2. Nhập câu sai danh từ số ít/số nhiều 3. Nhấn nút [Check] | D14: 2. I have three brother in my family. | E14: 1. Hiển thị giao diện chính của trang website. 3. Hệ thống phát hiện lỗi ở từ "brother", đánh dấu và gợi ý sửa thành "brothers". | F14: Không | G14: Passed | H14: 46317 | I14: High
A15: GRAMMAR_CHECK_06 | B15: Kiểm tra phát hiện lỗi dùng sai giới từ | C15: 1. Truy cập trang website 2. Nhập câu dùng sai giới từ 3. Nhấn nút [Check] | D15: 2. She is good in math. | E15: 1. Hiển thị giao diện chính của trang website. 3. Hệ thống phát hiện giới từ "in" dùng sai, đánh dấu và gợi ý sửa thành "at". | F15: Không | G15: Passed | H15: 46317 | I15: High
A16: GRAMMAR_CHECK_07 | B16: Kiểm tra phát hiện nhiều lỗi trong cùng một câu | C16: 1. Truy cập trang website 2. Nhập câu chứa nhiều lỗi ngữ pháp cùng lúc 3. Nhấn nút [Check] | D16: 2. She go to the market and buy vegetables yesterday. | E16: 1. Hiển thị giao diện chính của trang website. 3. Hệ thống trả về hai lỗi "go" → "went" và "buy" → "bought", đồng thời đánh dấu và liệt kê đầy đủ trên giao diện. | F16: Không | G16: Passed | H16: 46317 | I16: High
A17: GRAMMAR_CHECK_08 | B17: Kiểm tra khi không nhập văn bản | C17: 1. Truy cập trang website 2. Để trống ô nhập văn bản 3. Nhấn nút [Check] | D17: 2. (Để trống, không nhập gì) | E17: 1. Hiển thị giao diện chính của trang website. 3. Hệ thống hiển thị thông báo "Please enter text" và không gửi yêu cầu tới API. | F17: Không | G17: Passed | H17: 46317 | I17: High
A18: GRAMMAR_CHECK_09 | B18: Kiểm tra khi chỉ nhập dấu cách | C18: 1. Truy cập trang website 2. Chỉ nhập các dấu cách vào ô nhập văn bản 3. Nhấn nút [Check] | D18: 2. (Chỉ nhập 5 dấu cách) | E18: 1. Hiển thị giao diện chính của trang website. 3. Hệ thống xử lý như văn bản rỗng, hiển thị thông báo "Please enter text" và không gửi yêu cầu tới API. | F18: Không | G18: Passed | H18: 46317 | I18: High
A19: GRAMMAR_CHECK_10 | B19: Kiểm tra đoạn văn gồm nhiều câu có lỗi | C19: 1. Truy cập trang website 2. Nhập đoạn văn gồm nhiều câu có lỗi ngữ pháp 3. Nhấn nút [Check] | D19: 2. My sister have a cat. It are very lazy. I love it. | E19: 1. Hiển thị giao diện chính của trang website. 3. Hệ thống kiểm tra toàn bộ đoạn văn, phát hiện "have" → "has" và "are" → "is", đồng thời hiển thị bản đã sửa. | F19: Không | G19: Passed | H19: 46317 | I19: High
A20: GRAMMAR_CHECK_11 | B20: Kiểm tra khi nhập văn bản dài đúng 1000 ký tự (bằng giới hạn) | C20: 1. Truy cập trang website 2. Nhập văn bản dài đúng 1000 ký tự 3. Nhấn nút [Check] | D20: 2. Chuỗi 1000 ký tự (ví dụ: ký tự "a" lặp lại 1000 lần) | E20: 1. Hiển thị giao diện chính của trang website. 3. Hệ thống xử lý văn bản bình thường, không hiển thị thông báo vượt giới hạn. | F20: Không | G20: Passed | H20: 46317 | I20: High
A21: GRAMMAR_CHECK_12 | B21: Kiểm tra khi nhập văn bản dài 1001 ký tự (vượt giới hạn) | C21: 1. Truy cập trang website 2. Nhập văn bản dài 1001 ký tự 3. Nhấn nút [Check] | D21: 2. Chuỗi 1001 ký tự (ví dụ: ký tự "a" lặp lại 1001 lần) | E21: 1. Hiển thị giao diện chính của trang website. 3. Hệ thống hiển thị thông báo "Text is too long (max 1000 characters)". | F21: Không | G21: Passed | H21: 46317 | I21: High
B22: Hiển thị kết quả
A23: GRAMMAR_RESULT_01 | B23: Kiểm tra hiển thị khu vực kết quả phân tích | C23: 1. Truy cập trang website 2. Nhập văn bản cần kiểm tra vào ô nhập 3. Nhấn nút [Check] 4. Quan sát khu vực [Analysis Result] | D23: 2. He go to work by bus every morning. | E23: 1. Hiển thị giao diện chính của trang website. 4. Hiển thị văn bản gốc (Original) có đánh dấu lỗi, văn bản đã sửa (Corrected version) và danh sách [Detected Errors (n)]. | F23: Không | G23: Passed | H23: 46317 | I23: High
A24: GRAMMAR_RESULT_02 | B24: Kiểm tra số lượng lỗi trong mục Detected Errors | C24: 1. Truy cập trang website 2. Nhập văn bản cần kiểm tra vào ô nhập 3. Nhấn nút [Check] 4. Quan sát mục [Detected Errors] | D24: 2. She go to the market and buy vegetables yesterday. | E24: 1. Hiển thị giao diện chính của trang website. 4. Tiêu đề hiển thị đúng số lỗi (2) và có 2 thẻ lỗi tương ứng. | F24: Không | G24: Passed | H24: 46317 | I24: High
A25: GRAMMAR_RESULT_03 | B25: Kiểm tra nội dung thẻ lỗi trong Detected Errors | C25: 1. Truy cập trang website 2. Nhập văn bản cần kiểm tra vào ô nhập 3. Nhấn nút [Check] 4. Xem thẻ lỗi đầu tiên trong mục [Detected Errors] | D25: 2. She go to the market yesterday. | E25: 1. Hiển thị giao diện chính của trang website. 4. Thẻ lỗi hiển thị nhãn loại lỗi (ví dụ TENSE), gợi ý sửa dạng "go → went" và phần giải thích bằng tiếng Anh. | F25: Không | G25: Passed | H25: 46317 | I25: High
A26: GRAMMAR_RESULT_04 | B26: Kiểm tra đánh dấu từ lỗi trong văn bản gốc | C26: 1. Truy cập trang website 2. Nhập văn bản cần kiểm tra vào ô nhập 3. Nhấn nút [Check] 4. Quan sát văn bản gốc (Original) trong [Analysis Result] | D26: 2. We is ready for the exam. | E26: 1. Hiển thị giao diện chính của trang website. 4. Từ lỗi "is" được đánh dấu nổi bật; các từ đúng không bị đánh dấu. | F26: Không | G26: Passed | H26: 46317 | I26: Medium
A27: GRAMMAR_RESULT_05 | B27: Kiểm tra hiển thị văn bản đã sửa (Corrected version) | C27: 1. Truy cập trang website 2. Nhập văn bản cần kiểm tra vào ô nhập 3. Nhấn nút [Check] 4. Quan sát mục [Corrected version] | D27: 2. I have three brother in my family. | E27: 1. Hiển thị giao diện chính của trang website. 4. Văn bản đã sửa hiển thị "I have three brothers in my family." | F27: Không | G27: Passed | H27: 46317 | I27: High
A28: GRAMMAR_RESULT_06 | B28: Kiểm tra nút Export kết quả phân tích | C28: 1. Truy cập trang website 2. Nhập văn bản cần kiểm tra vào ô nhập 3. Nhấn nút [Check] 4. Nhấn nút [EXPORT] trong phần [Analysis Result] | D28: 2. My sister have a cat. | E28: 1. Hiển thị giao diện chính của trang website. 4. Hệ thống xuất kết quả phân tích thành công theo thiết kế (tải tệp về máy) và nội dung tệp khớp với kết quả hiển thị. | F28: Không | G28: Passed | H28: 46317 | I28: Medium
B29: API
A30: GRAMMAR_API_01 | B30: Kiểm tra khi API phản hồi quá chậm (timeout) | C30: 1. Truy cập trang website 2. Nhập câu đúng ngữ pháp 3. Giả lập API phản hồi quá thời gian chờ 4. Nhấn nút [Check] | D30: 2. He works in a bank. | E30: 1. Hiển thị giao diện chính của trang website. 4. Hệ thống hiển thị thông báo lỗi "Cannot connect API" và cho phép nhấn [Check] để thử lại. | F30: Không | G30: Passed | H30: 46317 | I30: High
A31: GRAMMAR_API_02 | B31: Kiểm tra khi mất kết nối mạng | C31: 1. Truy cập trang website 2. Nhập câu đúng ngữ pháp 3. Ngắt kết nối mạng 4. Nhấn nút [Check] | D31: 2. We are studying English. | E31: 1. Hiển thị giao diện chính của trang website. 4. Hệ thống hiển thị thông báo lỗi và giữ nguyên nội dung đã nhập. | F31: Không | G31: Passed | H31: 46317 | I31: High
A32: GRAMMAR_API_03 | B32: Kiểm tra khi máy chủ trả lỗi HTTP 500 | C32: 1. Truy cập trang website 2. Nhập câu đúng ngữ pháp 3. Giả lập API trả về lỗi HTTP 500 4. Nhấn nút [Check] | D32: 2. My mother is cooking dinner. | E32: 1. Hiển thị giao diện chính của trang website. 4. Hệ thống hiển thị thông báo lỗi, ứng dụng không bị treo. | F32: Không | G32: Passed | H32: 46317 | I32: High
A33: GRAMMAR_API_04 | B33: Kiểm tra khi API trả về dữ liệu sai cấu trúc | C33: 1. Truy cập trang website 2. Nhập câu đúng ngữ pháp 3. Giả lập API trả về dữ liệu sai cấu trúc 4. Nhấn nút [Check] | D33: 2. I am a teacher. | E33: 1. Hiển thị giao diện chính của trang website. 4. Hệ thống hiển thị thông báo lỗi, ứng dụng không bị treo. | F33: Không | G33: Passed | H33: 46317 | I33: High
A34: GRAMMAR_API_05 | B34: Kiểm tra khi API AI-service lỗi và hệ thống dùng dữ liệu dự phòng (mock data) | C34: 1. Truy cập trang website 2. Nhập văn bản cần kiểm tra vào ô nhập 3. Giả lập AI-service không phản hồi 4. Nhấn nút [Check] | D34: 2. I am a teacher. | E34: 1. Hiển thị giao diện chính của trang website. 4. Hệ thống tự động dùng dữ liệu dự phòng (mock data) hoặc hiển thị thông báo lỗi theo thiết kế, ứng dụng không bị treo. | F34: Không | G34: Passed | H34: 46317 | I34: Medium

Sheet AI Rewrite
A2: Module Code | B2: AI Rewrite
A3: Test Requirement | B3: Kiểm thử chức năng gợi ý cải thiện câu viết
A4: Tester | B4: Nguyễn Thanh Thủy
A5: Passed | B5: Failed | C5: Untested | D5: Blocked | E5: Skipped | F5: Number of Test cases
A6: =COUNTIF($G$10:$G$995,"Passed") -> 23 | B6: =COUNTIF($G$10:$G$995,"Failed") -> 0 | C6: =COUNTIF($G$10:$G$995,"Untested") -> 0 | D6: =COUNTIF($G$10:$G$995,"Blocked") -> 0 | E6: =COUNTIF($G$10:$G$995,"Skipped") -> 0 | F6: =COUNTA($A$10:$A$995) -> 23
A8: ID | B8: Test Case Description | C8: Test Case Procedure | D8: Test Data | E8: Expected Output | F8: Inter-test case Dependence | G8: Result | H8: Test date | I8: Priority | J8: Note
B9: Gợi ý cải thiện câu viết
A10: AI_REWRITE_01 | B10: Kiểm tra viết lại câu tiếng Anh hợp lệ | C10: 1. Truy cập trang website 2. Nhập câu tiếng Anh cần viết lại 3. Nhấn nút [Check] 4. Nhấn nút [Rewrite with AI] tại mục [AI Rewrite Suggestion] | D10: 2. I want to improve my English writing. | E10: 1. Hiển thị giao diện chính của trang website. 4. Hệ thống trả về bản viết lại tự nhiên tại mục [Improved Version], kèm phần [IMPROVEMENTS] và [SUMMARY] giải thích thay đổi. | F10: GRAMMAR_CHECK_01 | G10: Passed | H10: 46318 | I10: High
A11: AI_REWRITE_02 | B11: Kiểm tra viết lại đoạn gồm nhiều câu | C11: 1. Truy cập trang website 2. Nhập đoạn gồm nhiều câu 3. Nhấn nút [Check] 4. Nhấn nút [Rewrite with AI] tại mục [AI Rewrite Suggestion] | D11: 2. I study English every day. I want to speak better. | E11: 1. Hiển thị giao diện chính của trang website. 4. Cả đoạn được viết lại và phần [SUMMARY] phản ánh các thay đổi chính. | F11: GRAMMAR_CHECK_01 | G11: Passed | H11: 46318 | I11: High
A12: AI_REWRITE_03 | B12: Kiểm tra viết lại văn bản nhiều dòng | C12: 1. Truy cập trang website 2. Nhập văn bản gồm nhiều dòng (nhấn Enter giữa các dòng) 3. Nhấn nút [Check] 4. Nhấn nút [Rewrite with AI] tại mục [AI Rewrite Suggestion] | D12: 2. Dòng 1: "I like English." Dòng 2: "It help me find better jobs." | E12: 1. Hiển thị giao diện chính của trang website. 4. Mọi dòng đều được xử lý; kết quả là đoạn văn liền mạch và giữ nguyên ý gốc. | F12: GRAMMAR_CHECK_01 | G12: Passed | H12: 46318 | I12: High
A13: AI_REWRITE_04 | B13: Kiểm tra viết lại văn bản chứa lỗi ngữ pháp và chính tả | C13: 1. Truy cập trang website 2. Nhập câu chứa lỗi ngữ pháp và chính tả 3. Nhấn nút [Check] 4. Nhấn nút [Rewrite with AI] tại mục [AI Rewrite Suggestion] | D13: 2. She go to scool every days. | E13: 1. Hiển thị giao diện chính của trang website. 4. Lỗi ngữ pháp và chính tả được sửa trong [Improved Version] (ví dụ "She goes to school every day."). | F13: GRAMMAR_CHECK_01 | G13: Passed | H13: 46318 | I13: High
A14: AI_REWRITE_05 | B14: Kiểm tra viết lại văn bản tiếng Việt | C14: 1. Truy cập trang website 2. Nhập câu tiếng Việt 3. Nhấn nút [Check] 4. Nhấn nút [Rewrite with AI] tại mục [AI Rewrite Suggestion] | D14: 2. Tôi muốn học tiếng Anh. | E14: 1. Hiển thị giao diện chính của trang website. 4. Hệ thống xử lý theo thiết kế, ký tự tiếng Việt hiển thị đúng, không lỗi font và ứng dụng không bị lỗi. | F14: GRAMMAR_CHECK_01 | G14: Passed | H14: 46318 | I14: Medium
A15: AI_REWRITE_06 | B15: Kiểm tra viết lại văn bản có ký tự đặc biệt | C15: 1. Truy cập trang website 2. Nhập văn bản chứa ký tự đặc biệt 3. Nhấn nút [Check] 4. Nhấn nút [Rewrite with AI] tại mục [AI Rewrite Suggestion] | D15: 2. English!!! @school #learning | E15: 1. Hiển thị giao diện chính của trang website. 4. Ứng dụng không lỗi và trả về bản viết lại hợp lệ (ký tự thừa có thể được lược bỏ). | F15: GRAMMAR_CHECK_01 | G15: Passed | H15: 46318 | I15: Medium
A16: AI_REWRITE_07 | B16: Kiểm tra viết lại văn bản có số liệu và ngày tháng | C16: 1. Truy cập trang website 2. Nhập văn bản có số liệu và ngày tháng 3. Nhấn nút [Check] 4. Nhấn nút [Rewrite with AI] tại mục [AI Rewrite Suggestion] | D16: 2. I studied for 2 hours on 27/06/2026. | E16: 1. Hiển thị giao diện chính của trang website. 4. Số liệu và ngày tháng được giữ đúng trong bản viết lại. | F16: GRAMMAR_CHECK_01 | G16: Passed | H16: 46318 | I16: High
A17: AI_REWRITE_08 | B17: Kiểm tra viết lại câu đã đúng ngữ pháp | C17: 1. Truy cập trang website 2. Nhập câu đúng ngữ pháp 3. Nhấn nút [Check] 4. Nhấn nút [Rewrite with AI] tại mục [AI Rewrite Suggestion] | D17: 2. My brother plays football every weekend. | E17: 1. Hiển thị giao diện chính của trang website. 4. Hệ thống trả về bản viết lại hợp lệ, giữ nguyên ý và không báo lỗi. | F17: Không | G17: Passed | H17: 46318 | I17: Medium
A18: AI_REWRITE_09 | B18: Kiểm tra viết lại văn bản chứa mã HTML | C18: 1. Truy cập trang website 2. Nhập văn bản chứa thẻ HTML 3. Nhấn nút [Check] 4. Nhấn nút [Rewrite with AI] tại mục [AI Rewrite Suggestion] | D18: 2. <b>Hello</b> <script>alert('xss')</script> | E18: 1. Hiển thị giao diện chính của trang website. 4. Hệ thống không thực thi mã HTML/script, hiển thị nội dung như chữ thường và ứng dụng không bị lỗi. | F18: Không | G18: Passed | H18: 46318 | I18: High
A19: AI_REWRITE_10 | B19: Kiểm tra khi không nhập văn bản | C19: 1. Truy cập trang website 2. Để trống ô nhập văn bản 3. Nhấn nút [Rewrite with AI] | D19: 2. (Để trống, không nhập gì) | E19: 1. Hiển thị giao diện chính của trang website. 3. Hệ thống hiển thị thông báo "Please enter text" và không gửi yêu cầu tới API. | F19: GRAMMAR_CHECK_01 | G19: Passed | H19: 46318 | I19: High
A20: AI_REWRITE_11 | B20: Kiểm tra khi văn bản chỉ chứa dấu cách | C20: 1. Truy cập trang website 2. Chỉ nhập các dấu cách vào ô nhập văn bản 3. Nhấn nút [Rewrite with AI] | D20: 2. (Chỉ nhập 5 dấu cách) | E20: 1. Hiển thị giao diện chính của trang website. 3. Hệ thống xử lý như văn bản rỗng, hiển thị thông báo "Please enter text" và không gửi yêu cầu tới API. | F20: GRAMMAR_CHECK_01 | G20: Passed | H20: 46318 | I20: High
A21: AI_REWRITE_12 | B21: Kiểm tra khi nhấn Rewrite liên tiếp nhiều lần | C21: 1. Truy cập trang website 2. Nhập câu cần viết lại 3. Nhấn nút [Check] 4. Nhấn nút [Rewrite with AI] liên tiếp nhiều lần | D21: 2. I want to write better. | E21: 1. Hiển thị giao diện chính của trang website. 4. Nút bị vô hiệu hóa và hiển thị "Rewriting..." khi đang xử lý; chỉ một yêu cầu được gửi đi. | F21: GRAMMAR_CHECK_01 | G21: Passed | H21: 46318 | I21: High
B22: Hiển thị kết quả
A23: AI_REWRITE_RESULT_01 | B23: Kiểm tra hiển thị bản viết lại tại mục Improved Version | C23: 1. Truy cập trang website 2. Nhập văn bản cần kiểm tra vào ô nhập 3. Nhấn nút [Check] 4. Nhấn nút [Rewrite with AI] 5. Quan sát kết quả | D23: 2. I want to improve my English writing. | E23: 1. Hiển thị giao diện chính của trang website. 5. Hiển thị bản viết lại tại mục [Improved Version] khác với văn bản gốc và giữ nguyên ý nghĩa. | F23: Không | G23: Passed | H23: 46318 | I23: High
A24: AI_REWRITE_RESULT_02 | B24: Kiểm tra hiển thị phần IMPROVEMENTS theo nhóm thay đổi | C24: 1. Truy cập trang website 2. Nhập văn bản cần kiểm tra vào ô nhập 3. Nhấn nút [Check] 4. Nhấn nút [Rewrite with AI] 5. Quan sát phần [IMPROVEMENTS] | D24: 2. I very like study English because it is important. | E24: 1. Hiển thị giao diện chính của trang website. 5. Các cải tiến được chia theo nhóm Vocabulary, Structure, Style; mỗi mục có Original, Improved và Reason. | F24: Không | G24: Passed | H24: 46318 | I24: High
A25: AI_REWRITE_RESULT_03 | B25: Kiểm tra hiển thị phần SUMMARY | C25: 1. Truy cập trang website 2. Nhập văn bản cần kiểm tra vào ô nhập 3. Nhấn nút [Check] 4. Nhấn nút [Rewrite with AI] 5. Quan sát phần [SUMMARY] | D25: 2. I want to improve my English writing. | E25: 1. Hiển thị giao diện chính của trang website. 5. Phần [SUMMARY] hiển thị tóm tắt ngắn gọn các thay đổi chính, khớp với nội dung [IMPROVEMENTS]. | F25: Không | G25: Passed | H25: 46318 | I25: Medium
A26: AI_REWRITE_RESULT_04 | B26: Kiểm tra trạng thái đang xử lý khi viết lại | C26: 1. Truy cập trang website 2. Nhập văn bản cần kiểm tra vào ô nhập 3. Nhấn nút [Check] 4. Nhấn nút [Rewrite with AI] 5. Quan sát nút ngay sau khi nhấn | D26: 2. I want to improve my English writing. | E26: 1. Hiển thị giao diện chính của trang website. 5. Nút hiển thị "Rewriting..." và bị vô hiệu hóa trong khi chờ; sau khi có kết quả nút trở lại trạng thái ban đầu. | F26: Không | G26: Passed | H26: 46318 | I26: High
A27: AI_REWRITE_RESULT_05 | B27: Kiểm tra nút Listen đọc bản viết lại | C27: 1. Truy cập trang website 2. Nhập văn bản cần kiểm tra vào ô nhập 3. Nhấn nút [Check] 4. Nhấn nút [Rewrite with AI] 5. Nhấn nút [Listen] tại mục [Improved Version] | D27: 2. I want to improve my English writing. | E27: 1. Hiển thị giao diện chính của trang website. 6. Hệ thống đọc to nội dung bản viết lại bằng giọng tiếng Anh và không phát sinh lỗi. | F27: Không | G27: Passed | H27: 46318 | I27: Medium
B28: API
A29: AI_REWRITE_API_01 | B29: Kiểm tra khi API phản hồi quá chậm (timeout) | C29: 1. Truy cập trang website 2. Nhập câu đúng ngữ pháp 3. Nhấn nút [Check] 4. Giả lập API phản hồi quá thời gian chờ 5. Nhấn nút [Rewrite with AI] tại mục [AI Rewrite Suggestion] | D29: 2. I am learning English. | E29: 1. Hiển thị giao diện chính của trang website. 5. Sau thời gian chờ (khoảng 30 giây) hiển thị thông báo lỗi và cho phép nhấn [Rewrite with AI] để thử lại. | F29: Không | G29: Passed | H29: 46318 | I29: High
A30: AI_REWRITE_API_02 | B30: Kiểm tra khi mất kết nối mạng | C30: 1. Truy cập trang website 2. Nhập câu đúng ngữ pháp 3. Nhấn nút [Check] 4. Ngắt kết nối mạng 5. Nhấn nút [Rewrite with AI] tại mục [AI Rewrite Suggestion] | D30: 2. I am learning English. | E30: 1. Hiển thị giao diện chính của trang website. 5. Hệ thống hiển thị thông báo lỗi và giữ nguyên nội dung đã nhập. | F30: Không | G30: Passed | H30: 46318 | I30: High
A31: AI_REWRITE_API_03 | B31: Kiểm tra khi máy chủ trả lỗi HTTP 500 | C31: 1. Truy cập trang website 2. Nhập câu đúng ngữ pháp 3. Nhấn nút [Check] 4. Giả lập API trả về lỗi HTTP 500 5. Nhấn nút [Rewrite with AI] tại mục [AI Rewrite Suggestion] | D31: 2. I am learning English. | E31: 1. Hiển thị giao diện chính của trang website. 5. Hệ thống hiển thị thông báo lỗi; ứng dụng không bị treo và các chức năng khác vẫn dùng được. | F31: Không | G31: Passed | H31: 46318 | I31: High
A32: AI_REWRITE_API_04 | B32: Kiểm tra khi vượt giới hạn tần suất (HTTP 429) | C32: 1. Truy cập trang website 2. Nhập câu đúng ngữ pháp 3. Nhấn nút [Check] 4. Giả lập API trả về lỗi HTTP 429 (ví dụ: mock API) 5. Nhấn nút [Rewrite with AI] | D32: 2. I am learning English. | E32: 1. Hiển thị giao diện chính của trang website. 5. Hệ thống hiển thị thông báo lỗi từ máy chủ, ví dụ "Groq API error (status code 429)". | F32: Không | G32: Passed | H32: 46318 | I32: High
A33: AI_REWRITE_API_05 | B33: Kiểm tra khi API trả về phản hồi rỗng | C33: 1. Truy cập trang website 2. Nhập câu đúng ngữ pháp 3. Nhấn nút [Check] 4. Giả lập API trả về phản hồi rỗng 5. Nhấn nút [Rewrite with AI] tại mục [AI Rewrite Suggestion] | D33: 2. I am learning English. | E33: 1. Hiển thị giao diện chính của trang website. 5. Hệ thống không hiển thị kết quả sai và báo lỗi phù hợp. | F33: Không | G33: Passed | H33: 46318 | I33: High
A34: AI_REWRITE_API_06 | B34: Kiểm tra khi phản hồi sai cấu trúc dữ liệu | C34: 1. Truy cập trang website 2. Nhập câu đúng ngữ pháp 3. Nhấn nút [Check] 4. Giả lập API trả về dữ liệu không đúng định dạng REWRITTEN TEXT / IMPROVEMENTS / SUMMARY 5. Nhấn nút [Rewrite with AI] tại mục [AI Rewrite Suggestion] | D34: 2. I am learning English. | E34: 1. Hiển thị giao diện chính của trang website. 5. Ứng dụng không bị treo, không hiển thị dữ liệu sai và hiển thị thông báo lỗi. | F34: Không | G34: Passed | H34: 46318 | I34: High

Sheet Vocab Lookup
A2: Module Code | B2: Vocab Lookup
A3: Test Requirement | B3: Kiểm thử chức năng tra cứu từ vựng
A4: Tester | B4: Nguyễn Thanh Thủy
A5: Passed | B5: Failed | C5: Untested | D5: Blocked | E5: Skipped | F5: Number of Test cases
A6: =COUNTIF($G$10:$G$989,"Passed") -> 24 | B6: =COUNTIF($G$10:$G$989,"Failed") -> 2 | C6: =COUNTIF($G$10:$G$989,"Untested") -> 0 | D6: =COUNTIF($G$10:$G$989,"Blocked") -> 0 | E6: =COUNTIF($G$10:$G$989,"Skipped") -> 0 | F6: =COUNTA($A$10:$A$989) -> 26
A8: ID | B8: Test Case Description | C8: Test Case Procedure | D8: Test Data | E8: Expected Output | F8: Inter-test case Dependence | G8: Result | H8: Test date | I8: Priority | J8: Note
B9: Tra cứu từ
A10: VOCAB_LOOKUP_01 | B10: Kiểm tra tra cứu một từ tiếng Anh hợp lệ | C10: 1. Truy cập trang website 2. Nhập văn bản chứa từ cần tra rồi nhấn nút [Check] 3. Bôi chọn từ cần tra trong phần [Analysis Result] 4. Quan sát popup tra cứu | D10: 3. Từ khóa: "student" | E10: 1. Hiển thị giao diện chính của trang website. 4. Popup hiển thị thông tin của từ "student" gồm từ loại, phiên âm và định nghĩa tiếng Anh. | F10: Không | G10: Passed | H10: 46319 | I10: High
A11: VOCAB_LOOKUP_02 | B11: Kiểm tra tra cứu từ viết hoa toàn bộ | C11: 1. Truy cập trang website 2. Nhập văn bản chứa từ cần tra rồi nhấn nút [Check] 3. Bôi chọn từ viết hoa toàn bộ trong phần [Analysis Result] 4. Quan sát popup tra cứu | D11: 3. Từ khóa: "STUDENT" | E11: 1. Hiển thị giao diện chính của trang website. 4. Hệ thống không phân biệt hoa/thường và hiển thị kết quả của từ "student". | F11: Không | G11: Passed | H11: 46319 | I11: High
A12: VOCAB_LOOKUP_03 | B12: Kiểm tra tra cứu từ có khoảng trắng đầu và cuối | C12: 1. Truy cập trang website 2. Nhập văn bản chứa từ cần tra rồi nhấn nút [Check] 3. Bôi chọn từ có kèm khoảng trắng ở đầu và cuối 4. Quan sát popup tra cứu | D12: 3. Từ khóa: " student " | E12: 1. Hiển thị giao diện chính của trang website. 4. Khoảng trắng thừa được loại bỏ và hiển thị đúng kết quả của từ "student". | F12: Không | G12: Passed | H12: 46319 | I12: High
A13: VOCAB_LOOKUP_04 | B13: Kiểm tra tra cứu từ không có trong từ điển | C13: 1. Truy cập trang website 2. Nhập văn bản chứa từ cần tra rồi nhấn [Check] 3. Bôi chọn từ không có trong từ điển 4. Quan sát popup tra cứu | D13: 3. Từ khóa: "asdfghxyz" | E13: 1. Hiển thị giao diện chính của trang website. 4. Hệ thống hiển thị thông báo không tìm thấy từ, giao diện không bị lỗi. | F13: Không | G13: Passed | H13: 46319 | I13: High
A14: VOCAB_LOOKUP_05 | B14: Kiểm tra tra cứu từ có chứa ký tự đặc biệt | C14: 1. Truy cập trang website 2. Nhập văn bản chứa từ cần tra rồi nhấn [Check] 3. Bôi chọn từ có chứa ký tự đặc biệt 4. Quan sát popup tra cứu | D14: 3. Từ khóa: "@@@student###" | E14: 1. Hiển thị giao diện chính của trang website. 4. Hệ thống làm sạch ký tự lạ hoặc hiển thị thông báo phù hợp, không phát sinh lỗi. | F14: Không | G14: Failed | H14: 46319 | I14: High
A15: VOCAB_LOOKUP_06 | B15: Kiểm tra khi bôi chọn vùng chỉ chứa khoảng trắng | C15: 1. Truy cập trang website 2. Nhập văn bản chứa từ cần tra rồi nhấn nút [Check] 3. Bôi chọn vùng chỉ chứa khoảng trắng 4. Quan sát giao diện | D15: 3. Vùng chọn: 5 dấu cách | E15: 1. Hiển thị giao diện chính của trang website. 4. Hệ thống không gửi yêu cầu tra cứu và popup không được kích hoạt. | F15: Không | G15: Passed | H15: 46319 | I15: High
A16: VOCAB_LOOKUP_07 | B16: Kiểm tra tra cứu liên tiếp hai từ khác nhau | C16: 1. Truy cập trang website 2. Nhập văn bản chứa từ cần tra rồi nhấn nút [Check] 3. Bôi chọn từ cần tra trong phần [Analysis Result] 4. Bôi chọn tiếp một từ khác khi popup đang hiển thị 5. Quan sát popup tra cứu | D16: 3. Từ thứ nhất: "student" 4. Từ thứ hai: "teacher" | E16: 1. Hiển thị giao diện chính của trang website. 5. Popup cập nhật theo từ mới và không lẫn dữ liệu của từ trước. | F16: Không | G16: Passed | H16: 46319 | I16: High
A17: VOCAB_LOOKUP_08 | B17: Kiểm tra tra cứu từ khi API phản hồi chậm | C17: 1. Truy cập trang website 2. Nhập văn bản chứa từ cần tra rồi nhấn nút [Check] 3. Giả lập API từ điển phản hồi chậm 4. Bôi chọn từ cần tra trong phần [Analysis Result] 5. Quan sát popup tra cứu | D17: 4. Từ khóa: "communication" | E17: 1. Hiển thị giao diện chính của trang website. 5. Popup hiển thị trạng thái đang tải để người dùng không hiểu nhầm là không có kết quả. | F17: Không | G17: Passed | H17: 46319 | I17: High
B18: Hiển thị nghĩa
A19: VOCAB_MEANING_01 | B19: Kiểm tra hiển thị nghĩa của từ hợp lệ | C19: 1. Truy cập trang website 2. Nhập văn bản chứa từ cần tra rồi nhấn nút [Check] 3. Bôi chọn từ cần tra trong phần [Analysis Result] 4. Xem phần định nghĩa của từ trong popup | D19: 3. Từ khóa: "student" | E19: 1. Hiển thị giao diện chính của trang website. 4. Popup hiển thị định nghĩa tiếng Anh của từ "student" lấy từ Free Dictionary API. | F19: Không | G19: Passed | H19: 46319 | I19: High
A20: VOCAB_MEANING_02 | B20: Kiểm tra hiển thị nghĩa của từ có nhiều nghĩa | C20: 1. Truy cập trang website 2. Nhập văn bản chứa từ cần tra rồi nhấn nút [Check] 3. Bôi chọn từ có nhiều nghĩa 4. Xem phần định nghĩa của từ trong popup | D20: 3. Từ khóa: "book" | E20: 1. Hiển thị giao diện chính của trang website. 4. Hiển thị đầy đủ các nghĩa phổ biến và tách bạch từng nghĩa theo từng từ loại. | F20: Không | G20: Passed | H20: 46319 | I20: High
A21: VOCAB_MEANING_03 | B21: Kiểm tra khi API trả về dữ liệu thiếu nghĩa | C21: 1. Truy cập trang website 2. Nhập văn bản chứa từ cần tra rồi nhấn nút [Check] 3. Giả lập API từ điển trả về dữ liệu không có định nghĩa 4. Bôi chọn từ cần tra trong phần [Analysis Result] 5. Xem phần định nghĩa của từ trong popup | D21: 4. Từ khóa: "example" | E21: 1. Hiển thị giao diện chính của trang website. 5. Không hiển thị vùng định nghĩa trống gây khó hiểu; hiển thị thông báo chưa có dữ liệu hoặc ẩn mục định nghĩa. | F21: Không | G21: Passed | H21: 46319 | I21: High
B22: Hiển thị phiên âm
A23: VOCAB_PHONETIC_01 | B23: Kiểm tra hiển thị phiên âm IPA | C23: 1. Truy cập trang website 2. Nhập văn bản chứa từ cần tra rồi nhấn nút [Check] 3. Bôi chọn từ cần tra trong phần [Analysis Result] 4. Xem phần phiên âm trong popup | D23: 3. Từ khóa: "student" | E23: 1. Hiển thị giao diện chính của trang website. 4. Hiển thị phiên âm IPA của hai giọng UK và US (ví dụ "/ˈstjuː.dənt/", "/ˈstuː.dənt/"). | F23: Không | G23: Passed | H23: 46319 | I23: High
A24: VOCAB_PHONETIC_02 | B24: Kiểm tra khi API không trả về phiên âm | C24: 1. Truy cập trang website 2. Nhập văn bản chứa từ cần tra rồi nhấn nút [Check] 3. Giả lập API từ điển không trả về phiên âm 4. Bôi chọn từ cần tra trong phần [Analysis Result] 5. Xem phần phiên âm trong popup | D24: 4. Từ khóa: "rareword" | E24: 1. Hiển thị giao diện chính của trang website. 5. Hệ thống ẩn mục phiên âm hoặc hiển thị thông báo phù hợp, không hiển thị vùng trống. | F24: Không | G24: Passed | H24: 46319 | I24: High
B25: Hiển thị từ loại
A26: VOCAB_POS_01 | B26: Kiểm tra hiển thị từ loại của từ | C26: 1. Truy cập trang website 2. Nhập văn bản chứa từ cần tra rồi nhấn nút [Check] 3. Bôi chọn từ cần tra trong phần [Analysis Result] 4. Xem phần từ loại trong popup | D26: 3. Từ khóa: "beautiful" | E26: 1. Hiển thị giao diện chính của trang website. 4. Hiển thị đúng từ loại, ví dụ "adjective". | F26: Không | G26: Passed | H26: 46319 | I26: High
A27: VOCAB_POS_02 | B27: Kiểm tra hiển thị từ có nhiều từ loại | C27: 1. Truy cập trang website 2. Nhập văn bản chứa từ cần tra rồi nhấn nút [Check] 3. Bôi chọn từ có nhiều từ loại 4. Xem phần từ loại trong popup | D27: 3. Từ khóa: "book" | E27: 1. Hiển thị giao diện chính của trang website. 4. Hiển thị các từ loại phù hợp (ví dụ noun và verb), tách bạch rõ ràng. | F27: Không | G27: Failed | H27: 46319 | I27: High
A28: VOCAB_POS_03 | B28: Kiểm tra khi API không trả về từ loại | C28: 1. Truy cập trang website 2. Nhập văn bản chứa từ cần tra rồi nhấn nút [Check] 3. Giả lập API từ điển không trả về từ loại 4. Bôi chọn từ cần tra trong phần [Analysis Result] 5. Xem phần từ loại trong popup | D28: 4. Từ khóa: "example" | E28: 1. Hiển thị giao diện chính của trang website. 5. Không hiển thị nhãn từ loại trống; hệ thống ẩn mục từ loại hoặc dùng phương án thay thế theo thiết kế. | F28: Không | G28: Passed | H28: 46319 | I28: High
B29: Popup tra cứu
A30: VOCAB_TOOLTIP_01 | B30: Kiểm tra popup xuất hiện khi chọn từ | C30: 1. Truy cập trang website 2. Nhập văn bản chứa từ cần tra rồi nhấn nút [Check] 3. Bôi chọn từ cần tra trong phần [Analysis Result] 4. Quan sát popup | D30: 3. Từ khóa: "student" | E30: 1. Hiển thị giao diện chính của trang website. 4. Popup hiển thị nhanh, gần vị trí từ được chọn, với thông tin ngắn gọn gồm từ loại, phiên âm và định nghĩa. | F30: Không | G30: Passed | H30: 46319 | I30: High
A31: VOCAB_TOOLTIP_02 | B31: Kiểm tra đóng popup | C31: 1. Truy cập trang website 2. Nhập văn bản chứa từ cần tra rồi nhấn nút [Check] 3. Bôi chọn từ cần tra trong phần [Analysis Result] 4. Đóng popup bằng nút X hoặc nhấp ra ngoài popup 5. Quan sát giao diện | D31: 3. Từ khóa: "student" | E31: 1. Hiển thị giao diện chính của trang website. 5. Popup đóng lại khi bấm nút X hoặc nhấp ra ngoài và không che nội dung khác. | F31: Không | G31: Passed | H31: 46319 | I31: High
A32: VOCAB_TOOLTIP_03 | B32: Kiểm tra popup khi từ nằm sát mép màn hình | C32: 1. Truy cập trang website 2. Nhập văn bản chứa từ cần tra rồi nhấn nút [Check] 3. Bôi chọn từ nằm gần mép phải màn hình (trên màn hình nhỏ hoặc di động) 4. Quan sát popup | D32: 3. Từ nằm gần mép phải màn hình | E32: 1. Hiển thị giao diện chính của trang website. 4. Popup tự điều chỉnh vị trí, không bị cắt nội dung và không tràn khỏi màn hình. | F32: Không | G32: Passed | H32: 46319 | I32: High
A33: VOCAB_TOOLTIP_04 | B33: Kiểm tra popup trên thiết bị cảm ứng | C33: 1. Truy cập trang website 2. Nhập văn bản chứa từ cần tra rồi nhấn nút [Check] 3. Bôi chọn từ bằng thao tác chạm (trên điện thoại hoặc máy tính bảng) 4. Chạm ra ngoài popup | D33: 3. Từ khóa: "communication" | E33: 1. Hiển thị giao diện chính của trang website. 4. Popup hiển thị khi chọn từ bằng thao tác chạm. 5. Popup đóng lại khi chạm ra ngoài. | F33: Không | G33: Passed | H33: 46319 | I33: High
B34: Gợi ý cách dùng
A35: VOCAB_USAGE_01 | B35: Kiểm tra hiển thị cách dùng bằng nút See usage with AI | C35: 1. Truy cập trang website 2. Nhập văn bản chứa từ cần tra rồi nhấn nút [Check] 3. Bôi chọn từ cần tra trong phần [Analysis Result] 4. Nhấn nút [See usage with AI] trong popup | D35: 3. Từ khóa: "student" | E35: 1. Hiển thị giao diện chính của trang website. 4. Hiển thị 2-3 cách dùng gồm loại, nghĩa tiếng Việt, ví dụ tiếng Anh và bản dịch tiếng Việt của ví dụ. | F35: Không | G35: Passed | H35: 46319 | I35: High
A36: VOCAB_USAGE_02 | B36: Kiểm tra trạng thái đang tải khi tra cứu cách dùng | C36: 1. Truy cập trang website 2. Nhập văn bản chứa từ cần tra rồi nhấn nút [Check] 3. Bôi chọn từ cần tra trong phần [Analysis Result] 4. Nhấn nút [See usage with AI] trong popup 5. Quan sát popup ngay sau khi nhấn | D36: 3. Từ khóa: "communication" | E36: 1. Hiển thị giao diện chính của trang website. 4. Popup hiển thị trạng thái đang tải và không cho gửi trùng yêu cầu trong khi chờ kết quả. | F36: Không | G36: Passed | H36: 46319 | I36: Medium
A37: VOCAB_USAGE_03 | B37: Kiểm tra cách dùng của thành ngữ | C37: 1. Truy cập trang website 2. Nhập văn bản chứa từ cần tra rồi nhấn nút [Check] 3. Bôi chọn thành ngữ trong phần [Analysis Result] 4. Nhấn nút [See usage with AI] trong popup | D37: 3. Thành ngữ: "break the ice" | E37: 1. Hiển thị giao diện chính của trang website. 4. Hệ thống hiển thị cách dùng của thành ngữ kèm nghĩa tiếng Việt, ví dụ và bản dịch. | F37: Không | G37: Passed | H37: 46319 | I37: Medium
A38: VOCAB_USAGE_04 | B38: Kiểm tra khi API cách dùng (/lookup) bị lỗi | C38: 1. Truy cập trang website 2. Nhập văn bản chứa từ cần tra rồi nhấn nút [Check] 3. Bôi chọn từ cần tra trong phần [Analysis Result] 4. Giả lập API /lookup trả về lỗi 5. Nhấn nút [See usage with AI] trong popup | D38: 3. Từ khóa: "student" | E38: 1. Hiển thị giao diện chính của trang website. 5. Hiển thị thông báo lỗi phù hợp, phần thông tin từ điển trong popup vẫn được giữ nguyên và cho phép thử lại. | F38: Không | G38: Passed | H38: 46319 | I38: High
B39: API
A40: VOCAB_API_01 | B40: Kiểm tra khi API tra từ trả lỗi 500 | C40: 1. Truy cập trang website 2. Nhập văn bản chứa từ cần tra rồi nhấn nút [Check] 3. Giả lập API từ điển trả về lỗi HTTP 500 4. Bôi chọn từ cần tra trong phần [Analysis Result] 5. Quan sát phản hồi của giao diện | D40: 4. Từ khóa: "student" | E40: 1. Hiển thị giao diện chính của trang website. 5. Hiển thị thông báo lỗi, ứng dụng không bị treo và cho phép chọn lại từ để thử lại. | F40: Không | G40: Passed | H40: 46319 | I40: High
A41: VOCAB_API_02 | B41: Kiểm tra khi API tra từ quá thời gian chờ | C41: 1. Truy cập trang website 2. Nhập văn bản chứa từ cần tra rồi nhấn nút [Check] 3. Giả lập API từ điển phản hồi vượt thời gian chờ 4. Bôi chọn từ cần tra trong phần [Analysis Result] 5. Quan sát phản hồi của giao diện | D41: 4. Từ khóa: "teacher" | E41: 1. Hiển thị giao diện chính của trang website. 5. Hiển thị thông báo hết thời gian chờ, giữ nguyên từ đã chọn và cho phép thử lại. | F41: Không | G41: Passed | H41: 46319 | I41: High

Sheet Test Report
A1: TEST REPORT
B3: Project Name | C3: AI-Based English Grammar and Writing Improvement Tool | E3: Creator | G3: Nguyễn Thanh Thủy
B4: Project Code | E4: Reviewer/Approver
B5: Document Code | E5: Issue Date | G5: 46317
B6: Notes
B10: No | C10: Module code | D10: Passed | E10: Failed | F10: Untested | G10: Blocked | H10: Skipped | I10: Number of test cases
B11: 1 | C11: Text Input | D11: ='Text Input'!A6 -> 36 | E11: ='Text Input'!B6 -> 1 | F11: ='Text Input'!C6 -> 0 | G11: ='Text Input'!D6 -> 0 | H11: ='Text Input'!E6 -> 0 | I11: ='Text Input'!F6 -> 37
B12: =B11+1 -> 2 | C12: Grammar Check | D12: ='Grammar Check'!A6 -> 23 | E12: ='Grammar Check'!B6 -> 0 | F12: ='Grammar Check'!C6 -> 0 | G12: ='Grammar Check'!D6 -> 0 | H12: ='Grammar Check'!E6 -> 0 | I12: ='Grammar Check'!F6 -> 23
B13: =B12+1 -> 3 | C13: AI Rewrite | D13: ='AI Rewrite'!A6 -> 23 | E13: ='AI Rewrite'!B6 -> 0 | F13: ='AI Rewrite'!C6 -> 0 | G13: ='AI Rewrite'!D6 -> 0 | H13: ='AI Rewrite'!E6 -> 0 | I13: ='AI Rewrite'!F6 -> 23
B14: =B13+1 -> 4 | C14: Vocab Lookup | D14: ='Vocab Lookup'!A6 -> 24 | E14: ='Vocab Lookup'!B6 -> 2 | F14: ='Vocab Lookup'!C6 -> 0 | G14: ='Vocab Lookup'!D6 -> 0 | H14: ='Vocab Lookup'!E6 -> 0 | I14: ='Vocab Lookup'!F6 -> 26
C15: Total | D15: =SUM(D11:D14) -> 106 | E15: =SUM(E11:E14) -> 3 | F15: =SUM(F11:F14) -> 0 | G15: =SUM(G11:G14) -> 0 | H15: =SUM(H11:H14) -> 0 | I15: =SUM(I11:I14) -> 109
C19: Test coverage | D19: =ROUND((D15+E15)/I15*100,2) -> 100 | E19: %
C20: Test successful coverage | D20: =ROUND(D15/I15*100,2) -> 97.25 | E20: %
